<?xml version="1.0"?>

<robot name="visual">
  <link name="base_link">
 	<origin xyz="100 0 0 " rpy=" 0 0 0"/>
    <visual>
      <geometry>
         <cylinder length="0.01" radius="0.01"/>
      </geometry>
      <material name="yellow">
         <color rgba="1 1 0 1"/>
      </material>
    </visual>
  </link>

  <joint name="BaseToBottom" type="fixed">
    <origin xyz="0 0 0" rpy=" 1.57 0 1.57"/>
    <parent link="base_link"/>
    <child link="bottom"/>
    <limit effort="1.0" lower="0" upper="6" velocity="1.0"/>
    <axis xyz = "0 1 0"/>
  </joint>

  <link name="bottom">
 	<origin xyz="0 0 0 " rpy=" 0 0 0"/>
    <visual>
      <geometry>
        <mesh filename="package://robotarm/ScaraArm/Bottom.stl" scale="0.01 0.01 0.01"/>
      </geometry>
      <material name="blue"/>
    </visual>
  </link>

  <joint name="BottomToZ-Axis" type="prismatic">
    <origin xyz="0 1 0" rpy=" 0 1.57 0"/>
    <parent link="bottom"/>
    <child link="Z-Axis"/>
    <limit effort="1.0" lower="0" upper="6" velocity="1.0"/>
    <axis xyz = "0 1 0"/>
  </joint>

  <link name="Z-Axis">
    <origin xyz="0 0 0 " rpy=" 0 0 0"/>
    <visual>
      <geometry>
        <mesh filename="package://robotarm/ScaraArm/Z-Axis.stl" scale="0.01 0.01 0.01"/>
      </geometry>
      <material name="blue"/>
    </visual>
  </link>

  <joint name="BottomTop" type="fixed">
    <origin xyz="0 5.1 0" rpy=" 0 -1.57 3.14"/>
    <parent link="bottom"/>
    <child link="Top"/>
    <limit effort="1.0" lower="0" upper="6" velocity="1.0"/>
    <axis xyz = "0 0 1"/>
  </joint>

  <link name="Top">
    <origin xyz="0 0 0 " rpy=" 0 0 0"/>
    <visual>
      <geometry>
        <mesh filename="package://robotarm/ScaraArm/Top.stl" scale="0.01 0.01 0.01"/>
      </geometry>
      <material name="blue"/>
    </visual>
  </link>

  <joint name="Z-Axis-Link1Top" type="revolute">
    <origin xyz="0 0.23 0.64" rpy=" 0 0 0"/>
    <parent link="Z-Axis"/>
    <child link="Link1Top"/>
    <limit effort="1.0" lower="0" upper="6" velocity="1.0"/>
    <axis xyz = "0 1 0"/>
  </joint>

  <link name="Link1Top">
    <origin xyz="0 0 0 " rpy=" 0 0 0"/>
    <visual>
      <geometry>
        <mesh filename="package://robotarm/ScaraArm/Link_Top.stl" scale="0.01 0.01 0.01"/>
      </geometry>
      <material name="blue"/>
    </visual>
  </link>

  <joint name="Link1Top-Link1Bottom" type="fixed">
    <origin xyz="0 -0.46 0" rpy=" 0 0 0"/>
    <parent link="Link1Top"/>
    <child link="Link1Bottom"/>
    <limit effort="1.0" lower="0" upper="6" velocity="1.0"/>
    <axis xyz = "0 1 0"/>
  </joint>

  <link name="Link1Bottom">
    <origin xyz="0 0 0 " rpy=" 0 0 0"/>
    <visual>
      <geometry>
        <mesh filename="package://robotarm/ScaraArm/Link Bottom.stl" scale="0.01 0.01 0.01"/>
      </geometry>
      <material name="blue"/>
    </visual>
  </link>

  <joint name="Link1Top-Link1" type="fixed">
    <origin xyz="0 -0.23 -0.64" rpy=" 0 0 0"/>
    <parent link="Link1Top"/>
    <child link="Link1"/>
    <limit effort="1.0" lower="0" upper="6" velocity="1.0"/>
    <axis xyz = "0 0 1"/>
  </joint>

  <link name="Link1">
    <origin xyz="0 0 0 " rpy=" 0 0 0"/>
    <visual>
      <geometry>
        <mesh filename="package://robotarm/ScaraArm/Link 0.stl" scale="0.01 0.01 0.01"/>
      </geometry>
      <material name="blue"/>
    </visual>
  </link>



  <joint name="Bottom-SmoothRodL" type="fixed">
    <origin xyz="0.37 0.2 0.65" rpy=" 0 0 0"/>
    <parent link="bottom"/>
    <child link="SmoothRodL"/>
    <limit effort="1.0" lower="0" upper="6" velocity="1.0"/>
    <axis xyz = "0 0 1"/>
  </joint>

  <link name="SmoothRodL">
    <origin xyz="0 0 0 " rpy=" 0 0 0"/>
    <visual>
      <geometry>
        <mesh filename="package://robotarm/ScaraArm/SmoothRods.stl" scale="0.01 0.01 0.01"/>
      </geometry>
      <material name="blue"/>
    </visual>
  </link>

  <joint name="Bottom-SmoothRodR" type="fixed">
    <origin xyz="0.37 0.2 -0.65" rpy=" 0 0 0"/>
    <parent link="bottom"/>
    <child link="SmoothRodR"/>
    <limit effort="1.0" lower="0" upper="6" velocity="1.0"/>
    <axis xyz = "0 0 1"/>
  </joint>

  <link name="SmoothRodR">
    <origin xyz="0 0 0 " rpy=" 0 0 0"/>
    <visual>
      <geometry>
        <mesh filename="package://robotarm/ScaraArm/SmoothRods.stl" scale="0.01 0.01 0.01"/>
      </geometry>
      <material name="blue"/>
    </visual>
  </link>

  <joint name="Bottom-LeadScrew" type="fixed">
    <origin xyz="-0.04 0 0" rpy=" 0 0 0"/>
    <parent link="bottom"/>
    <child link="LeadScrew"/>
    <limit effort="1.0" lower="0" upper="6" velocity="1.0"/>
    <axis xyz = "0 0 1"/>
  </joint>

  <link name="LeadScrew">
    <origin xyz="0 0 0 " rpy=" 0 0 0"/>
    <visual>
      <geometry>
        <mesh filename="package://robotarm/ScaraArm/Leadscrew.stl" scale="0.01 0.01 0.01"/>
      </geometry>
      <material name="blue"/>
    </visual>
  </link>

  <joint name="Link1-Link2Top" type="revolute">
    <origin xyz="0 0.23 2.74" rpy=" 0 0 0"/>
    <parent link="Link1"/>
    <child link="Link2Top"/>
    <limit effort="1.0" lower="0" upper="6" velocity="1.0"/>
    <axis xyz = "0 1 0"/>
  </joint>

  <link name="Link2Top">
    <origin xyz="0 0 0 " rpy=" 0 0 0"/>
    <visual>
      <geometry>
        <mesh filename="package://robotarm/ScaraArm/Link_Top.stl" scale="0.01 0.01 0.01"/>
      </geometry>
      <material name="blue"/>
    </visual>
  </link>

  <joint name="Link2Top-Link2Bottom" type="fixed">
    <origin xyz="0 -0.46 0" rpy=" 0 0 0"/>
    <parent link="Link2Top"/>
    <child link="Link2Bottom"/>
    <limit effort="1.0" lower="0" upper="6" velocity="1.0"/>
    <axis xyz = "0 1 0"/>
  </joint>

  <link name="Link2Bottom">
    <origin xyz="0 0 0 " rpy=" 0 0 0"/>
    <visual>
      <geometry>
        <mesh filename="package://robotarm/ScaraArm/Link Bottom.stl" scale="0.01 0.01 0.01"/>
      </geometry>
      <material name="blue"/>
    </visual>
  </link>

  <joint name="Link2Top-Link2" type="fixed">
    <origin xyz="0 -0.23 -0.64" rpy=" 0 0 0"/>
    <parent link="Link2Top"/>
    <child link="Link2"/>
    <limit effort="1.0" lower="0" upper="6" velocity="1.0"/>
    <axis xyz = "0 0 1"/>
  </joint>


  <link name="Link2">
    <origin xyz="0 0 0  " rpy=" 0 0 0"/>
    <visual>
      <geometry>
        <mesh filename="package://robotarm/ScaraArm/Link 0.stl" scale="0.01 0.01 0.01"/>
      </geometry>
      <material name="blue"/>
    </visual>
  </link>

   
</robot>
